ftx {"error":"No such subaccount","success":false}

Current Time check is 2/32
Current Time check is 2/32
Current Time check is 2/32
^CProcess Process-3:
Traceback (most recent call last):
  File "/home/warproxxx/.local/lib/python3.8/site-packages/ccxt/base/exchange.py", line 588, in fetch
    response.raise_for_status()
  File "/home/warproxxx/.local/lib/python3.8/site-packages/requests/models.py", line 941, in raise_for_status
    raise HTTPError(http_error_msg, response=self)
requests.exceptions.HTTPError: 401 Client Error: UNAUTHORIZED for url: https://ftx.com/api/positions?showAvgPrice=true

During handling of the above exception, another exception occurred:

Traceback (most recent call last):
  File "/home/warproxxx/Desktop/Projects/algorithms/algos/altcoin/live_trader.py", line 110, in get_position
    pos = pd.DataFrame(self.exchange.private_get_positions(params={'showAvgPrice': True})['result'])
  File "/home/warproxxx/.local/lib/python3.8/site-packages/ccxt/base/exchange.py", line 465, in inner
    return entry(_self, **inner_kwargs)
  File "/home/warproxxx/.local/lib/python3.8/site-packages/ccxt/base/exchange.py", line 490, in request
    return self.fetch2(path, api, method, params, headers, body)
  File "/home/warproxxx/.local/lib/python3.8/site-packages/ccxt/base/exchange.py", line 486, in fetch2
    return self.fetch(request['url'], request['method'], request['headers'], request['body'])
  File "/home/warproxxx/.local/lib/python3.8/site-packages/ccxt/base/exchange.py", line 604, in fetch
    self.handle_errors(http_status_code, http_status_text, url, method, headers, http_response, json_response, request_headers, request_body)
  File "/home/warproxxx/.local/lib/python3.8/site-packages/ccxt/ftx.py", line 1508, in handle_errors
    raise ExchangeError(feedback)  # unknown message
ccxt.base.errors.ExchangeError: ftx {"error":"No such subaccount","success":false}
